2024-02-28 20:55:08,889 INFO    Thread-6 (_run_job):21489 [wandb_setup.py:_flush():76] Current SDK version is 0.16.3
2024-02-28 20:55:08,889 INFO    Thread-6 (_run_job):21489 [wandb_setup.py:_flush():76] Configure stats pid to 21489
2024-02-28 20:55:08,889 INFO    Thread-6 (_run_job):21489 [wandb_setup.py:_flush():76] Loading settings from /home/dofa/.config/wandb/settings
2024-02-28 20:55:08,889 INFO    Thread-6 (_run_job):21489 [wandb_setup.py:_flush():76] Loading settings from /home/dofa/Desktop/code/PMC/wandb/settings
2024-02-28 20:55:08,889 INFO    Thread-6 (_run_job):21489 [wandb_setup.py:_flush():76] Loading settings from environment variables: {'project': 'local_CAE_training_v0.2', 'entity': 'dofa_unsupervised', 'root_dir': '/home/dofa/Desktop/code/PMC', 'run_id': 'e5zgwexw', 'sweep_param_path': '/home/dofa/Desktop/code/PMC/wandb/sweep-vyex0pfa/config-e5zgwexw.yaml', 'sweep_id': 'vyex0pfa'}
2024-02-28 20:55:08,889 INFO    Thread-6 (_run_job):21489 [wandb_setup.py:_flush():76] Applying setup settings: {'_disable_service': False}
2024-02-28 20:55:08,889 INFO    Thread-6 (_run_job):21489 [wandb_setup.py:_flush():76] Inferring run settings from compute environment: {'program_relpath': 'src/machine_learning/un_supervised/neural_network/train_CAE.py', 'program_abspath': '/home/dofa/Desktop/code/PMC/src/machine_learning/un_supervised/neural_network/train_CAE.py', 'program': '/home/dofa/Desktop/code/PMC/src/machine_learning/un_supervised/neural_network/train_CAE.py'}
2024-02-28 20:55:08,889 INFO    Thread-6 (_run_job):21489 [wandb_init.py:_log_setup():526] Logging user logs to /home/dofa/Desktop/code/PMC/wandb/run-20240228_205508-e5zgwexw/logs/debug.log
2024-02-28 20:55:08,889 INFO    Thread-6 (_run_job):21489 [wandb_init.py:_log_setup():527] Logging internal logs to /home/dofa/Desktop/code/PMC/wandb/run-20240228_205508-e5zgwexw/logs/debug-internal.log
2024-02-28 20:55:08,889 INFO    Thread-6 (_run_job):21489 [wandb_init.py:init():566] calling init triggers
2024-02-28 20:55:08,889 INFO    Thread-6 (_run_job):21489 [wandb_init.py:init():573] wandb.init called with sweep_config: {'batch_size': 32, 'epochs': 30, 'learning_rate': 0.001}
config: {}
2024-02-28 20:55:08,889 INFO    Thread-6 (_run_job):21489 [wandb_init.py:init():616] starting backend
2024-02-28 20:55:08,889 INFO    Thread-6 (_run_job):21489 [wandb_init.py:init():620] setting up manager
2024-02-28 20:55:08,891 INFO    Thread-6 (_run_job):21489 [backend.py:_multiprocessing_setup():105] multiprocessing start_methods=fork,spawn,forkserver, using: spawn
2024-02-28 20:55:08,891 INFO    Thread-6 (_run_job):21489 [wandb_init.py:init():628] backend started and connected
2024-02-28 20:55:08,895 INFO    Thread-6 (_run_job):21489 [wandb_run.py:_config_callback():1343] config_cb None None {'batch_size': 32, 'epochs': 30, 'learning_rate': 0.001}
2024-02-28 20:55:08,896 INFO    Thread-6 (_run_job):21489 [wandb_init.py:init():720] updated telemetry
2024-02-28 20:55:08,899 INFO    Thread-6 (_run_job):21489 [wandb_init.py:init():753] communicating run to backend with 90.0 second timeout
2024-02-28 20:55:09,136 INFO    Thread-6 (_run_job):21489 [wandb_run.py:_on_init():2262] communicating current version
2024-02-28 20:55:09,235 INFO    Thread-6 (_run_job):21489 [wandb_run.py:_on_init():2271] got version response 
2024-02-28 20:55:09,235 INFO    Thread-6 (_run_job):21489 [wandb_init.py:init():804] starting run threads in backend
2024-02-28 20:55:10,963 ERROR   Thread-6 (_run_job):21489 [wandb_init.py:init():1204] error
Traceback (most recent call last):
  File "/home/dofa/miniconda3/envs/test/lib/python3.12/site-packages/wandb/sdk/wandb_init.py", line 1176, in init
    run = wi.init()
          ^^^^^^^^^
  File "/home/dofa/miniconda3/envs/test/lib/python3.12/site-packages/wandb/sdk/wandb_init.py", line 846, in init
    run._on_start()
  File "/home/dofa/miniconda3/envs/test/lib/python3.12/site-packages/wandb/sdk/wandb_run.py", line 2302, in _on_start
    self._run_status_checker.start()
  File "/home/dofa/miniconda3/envs/test/lib/python3.12/site-packages/wandb/sdk/wandb_run.py", line 206, in start
    self._stop_thread.start()
  File "/home/dofa/miniconda3/envs/test/lib/python3.12/threading.py", line 992, in start
    _start_new_thread(self._bootstrap, ())
RuntimeError: can't create new thread at interpreter shutdown
2024-02-28 20:55:11,019 INFO    Thread-6 (_run_job):21489 [wandb_run.py:_finish():1970] finishing run dofa_unsupervised/local_CAE_training_v0.2/e5zgwexw
2024-02-28 20:55:11,019 INFO    Thread-6 (_run_job):21489 [wandb_run.py:_atexit_cleanup():2210] got exitcode: 0
2024-02-28 20:55:11,019 INFO    Thread-6 (_run_job):21489 [wandb_run.py:_restore():2193] restore
2024-02-28 20:55:11,019 INFO    Thread-6 (_run_job):21489 [wandb_run.py:_restore():2199] restore done
2024-02-28 20:55:13,043 WARNING MsgRouterThr:21489 [router.py:message_loop():77] message_loop has been closed
