Trial 1 Complete [00h 00m 02s]
Best mean_absolute_error So Far: None
Total elapsed time: 00h 00m 02s
Search: Running Trial #2
Value             |Best Value So Far |Hyperparameter
40                |?                 |encoding_dim
0.0001            |?                 |lr
38                |?                 |batch_size
Trial 2 Complete [00h 00m 00s]
Best mean_absolute_error So Far: None
Total elapsed time: 00h 00m 02s
Search: Running Trial #3
Value             |Best Value So Far |Hyperparameter
40                |?                 |encoding_dim
0.001             |?                 |lr
34                |?                 |batch_size
[34m[1mwandb[39m[22m: [33mWARNING[39m The save_model argument by default saves the model in the HDF5 format that cannot save custom objects like subclassed models and custom layers. This behavior will be deprecated in a future release in favor of the SavedModel format. Meanwhile, the HDF5 model is saved as W&B files and the SavedModel as W&B Artifacts.
Traceback (most recent call last):
  File "/home/jean-sebastien/Documents/s7/PMC/venv/lib/python3.11/site-packages/keras_tuner/engine/base_tuner.py", line 250, in _try_run_and_update_trial
    self._run_and_update_trial(trial, *fit_args, **fit_kwargs)
  File "/home/jean-sebastien/Documents/s7/PMC/venv/lib/python3.11/site-packages/keras_tuner/engine/base_tuner.py", line 215, in _run_and_update_trial
    results = self.run_trial(trial, *fit_args, **fit_kwargs)
              ^^^^^^^^^^^^^^^^^^^^^^^^^^^^^^^^^^^^^^^^^^^^^^
  File "/home/jean-sebastien/Documents/s7/PMC/PMC/src/machine_learning/un_supervised/neural_network/hyper_parameters_tuner.py", line 57, in run_trial
    history = model.fit(
      ^^^^^^^^^^^^^^^^^^
TypeError: keras.src.engine.training.Model.fit() got multiple values for keyword argument 'callbacks'
Traceback (most recent call last):
  File "/home/jean-sebastien/Documents/s7/PMC/venv/lib/python3.11/site-packages/keras_tuner/engine/base_tuner.py", line 250, in _try_run_and_update_trial
    self._run_and_update_trial(trial, *fit_args, **fit_kwargs)
  File "/home/jean-sebastien/Documents/s7/PMC/venv/lib/python3.11/site-packages/keras_tuner/engine/base_tuner.py", line 215, in _run_and_update_trial
    results = self.run_trial(trial, *fit_args, **fit_kwargs)
              ^^^^^^^^^^^^^^^^^^^^^^^^^^^^^^^^^^^^^^^^^^^^^^
  File "/home/jean-sebastien/Documents/s7/PMC/PMC/src/machine_learning/un_supervised/neural_network/hyper_parameters_tuner.py", line 57, in run_trial
    history = model.fit(
      ^^^^^^^^^^^^^^^^^^
TypeError: keras.src.engine.training.Model.fit() got multiple values for keyword argument 'callbacks'
Traceback (most recent call last):
  File "/home/jean-sebastien/Documents/s7/PMC/venv/lib/python3.11/site-packages/keras_tuner/engine/base_tuner.py", line 250, in _try_run_and_update_trial
    self._run_and_update_trial(trial, *fit_args, **fit_kwargs)
  File "/home/jean-sebastien/Documents/s7/PMC/venv/lib/python3.11/site-packages/keras_tuner/engine/base_tuner.py", line 215, in _run_and_update_trial
    results = self.run_trial(trial, *fit_args, **fit_kwargs)
              ^^^^^^^^^^^^^^^^^^^^^^^^^^^^^^^^^^^^^^^^^^^^^^
  File "/home/jean-sebastien/Documents/s7/PMC/PMC/src/machine_learning/un_supervised/neural_network/hyper_parameters_tuner.py", line 57, in run_trial
    history = model.fit(
      ^^^^^^^^^^^^^^^^^^
TypeError: keras.src.engine.training.Model.fit() got multiple values for keyword argument 'callbacks'
Traceback (most recent call last):
  File "/home/jean-sebastien/Documents/s7/PMC/PMC/src/machine_learning/un_supervised/neural_network/./train.py", line 180, in <module>
    history = train_model.train_hp(args.EPOCHS_HP, args.NUM_TRIALS_HP, args.EXECUTION_PER_TRIAL_HP, args.PATH_RESULTS)
              ^^^^^^^^^^^^^^^^^^^^^^^^^^^^^^^^^^^^^^^^^^^^^^^^^^^^^^^^^^^^^^^^^^^^^^^^^^^^^^^^^^^^^^^^^^^^^^^^^^^^^^^^
  File "/home/jean-sebastien/Documents/s7/PMC/PMC/src/machine_learning/un_supervised/neural_network/./train.py", line 123, in train_hp
    hp_search = hp_tuner_instance.get_hp_search(args.HP_SEARCH, args.HP_NAME)
                ^^^^^^^^^^^^^^^^^^^^^^^^^^^^^^^^^^^^^^^^^^^^^^^^^^^^^^^^^^^^^
  File "/home/jean-sebastien/Documents/s7/PMC/PMC/src/machine_learning/un_supervised/neural_network/hyper_parameters_tuner.py", line 139, in get_hp_search
    self.tuner_search(tuner, self.callbacks[1:])
  File "/home/jean-sebastien/Documents/s7/PMC/PMC/src/machine_learning/un_supervised/neural_network/hyper_parameters_tuner.py", line 121, in tuner_search
    tuner.search(
  File "/home/jean-sebastien/Documents/s7/PMC/venv/lib/python3.11/site-packages/keras_tuner/engine/base_tuner.py", line 211, in search
    self.on_trial_end(trial)
  File "/home/jean-sebastien/Documents/s7/PMC/venv/lib/python3.11/site-packages/keras_tuner/engine/base_tuner.py", line 321, in on_trial_end
    self.oracle.end_trial(trial)
  File "/home/jean-sebastien/Documents/s7/PMC/venv/lib/python3.11/site-packages/keras_tuner/engine/oracle.py", line 105, in wrapped_func
    ret_val = func(*args, **kwargs)
              ^^^^^^^^^^^^^^^^^^^^^
  File "/home/jean-sebastien/Documents/s7/PMC/venv/lib/python3.11/site-packages/keras_tuner/engine/oracle.py", line 429, in end_trial
    self._check_consecutive_failures()
  File "/home/jean-sebastien/Documents/s7/PMC/venv/lib/python3.11/site-packages/keras_tuner/engine/oracle.py", line 382, in _check_consecutive_failures
    raise RuntimeError(
RuntimeError: Number of consecutive failures excceeded the limit of 3.
Traceback (most recent call last):
  File "/home/jean-sebastien/Documents/s7/PMC/venv/lib/python3.11/site-packages/keras_tuner/engine/base_tuner.py", line 250, in _try_run_and_update_trial
    self._run_and_update_trial(trial, *fit_args, **fit_kwargs)
  File "/home/jean-sebastien/Documents/s7/PMC/venv/lib/python3.11/site-packages/keras_tuner/engine/base_tuner.py", line 215, in _run_and_update_trial
    results = self.run_trial(trial, *fit_args, **fit_kwargs)
              ^^^^^^^^^^^^^^^^^^^^^^^^^^^^^^^^^^^^^^^^^^^^^^
  File "/home/jean-sebastien/Documents/s7/PMC/PMC/src/machine_learning/un_supervised/neural_network/hyper_parameters_tuner.py", line 57, in run_trial
    history = model.fit(
      ^^^^^^^^^^^^^^^^^^
TypeError: keras.src.engine.training.Model.fit() got multiple values for keyword argument 'callbacks'